Workbook

Sheet دفتر الأستاذ العام
A1: التاريخ | B1: الشهر | C1: البيان | D1: الفئة | E1: مدين | F1: دائن | H1: ملاحظة: هذا الشيت بالكامل (312 قيدًا) مولَّد بالذكاء الاصطناعي (Claude) لأغراض اختبار برومبت تحليل مالي — ليس بيانات شركة حقيقية.
A2: 2026-01-10 | B2: 1 | C2: مبيعات منتجات - فرع رئيسي | D2: مبيعات منتجات | F2: 314960
A3: 2026-01-25 | B3: 1 | C3: مبيعات منتجات - فرع فرعي | D3: مبيعات منتجات | F3: 193040
A4: 2026-01-10 | B4: 1 | C4: إيرادات خدمات - فرع رئيسي | D4: إيرادات خدمات | F4: 81840
A5: 2026-01-25 | B5: 1 | C5: إيرادات خدمات - فرع فرعي | D5: إيرادات خدمات | F5: 50160
A6: 2026-01-10 | B6: 1 | C6: إيرادات أخرى - فرع رئيسي | D6: إيرادات أخرى | F6: 3224
A7: 2026-01-25 | B7: 1 | C7: إيرادات أخرى - فرع فرعي | D7: إيرادات أخرى | F7: 1976
A8: 2026-01-10 | B8: 1 | C8: مواد خام مباشرة - دفعة أولى | D8: مواد خام مباشرة | E8: 110236
A9: 2026-01-25 | B9: 1 | C9: مواد خام مباشرة - دفعة ثانية | D9: مواد خام مباشرة | E9: 67564
A10: 2026-01-10 | B10: 1 | C10: أجور مباشرة - دفعة أولى | D10: أجور مباشرة | E10: 47244
A11: 2026-01-25 | B11: 1 | C11: أجور مباشرة - دفعة ثانية | D11: أجور مباشرة | E11: 28956
A12: 2026-01-10 | B12: 1 | C12: تكاليف صناعية غير مباشرة - دفعة أولى | D12: تكاليف صناعية غير مباشرة | E12: 31496
A13: 2026-01-25 | B13: 1 | C13: تكاليف صناعية غير مباشرة - دفعة ثانية | D13: تكاليف صناعية غير مباشرة | E13: 19304
A14: 2026-01-10 | B14: 1 | C14: رواتب وأجور إدارية - دفعة أولى | D14: رواتب وأجور إدارية | E14: 56420
A15: 2026-01-25 | B15: 1 | C15: رواتب وأجور إدارية - دفعة ثانية | D15: رواتب وأجور إدارية | E15: 34580
A16: 2026-01-01 | B16: 1 | C16: قيد إيجار الشهري | D16: إيجار | E16: 30000
A17: 2026-01-10 | B17: 1 | C17: تسويق وإعلان - دفعة أولى | D17: تسويق وإعلان | E17: 9610
A18: 2026-01-25 | B18: 1 | C18: تسويق وإعلان - دفعة ثانية | D18: تسويق وإعلان | E18: 5890
A19: 2026-01-10 | B19: 1 | C19: مرافق (كهرباء/مياه) - دفعة أولى | D19: مرافق (كهرباء/مياه) | E19: 5022
... A27: 2026-01-25 | B27: 1 | C27: مصروفات متنوعة / غير مصنَّف - دفعة ثانية | D27: مصروفات متنوعة / غير مصنَّف | E27: 1159
A28: 2026-02-10 | B28: 2 | C28: مبيعات منتجات - فرع رئيسي | D28: مبيعات منتجات | F28: 319920
A29: 2026-02-25 | B29: 2 | C29: مبيعات منتجات - فرع فرعي | D29: مبيعات منتجات | F29: 196080
A30: 2026-02-10 | B30: 2 | C30: إيرادات خدمات - فرع رئيسي | D30: إيرادات خدمات | F30: 83080
A31: 2026-02-25 | B31: 2 | C31: إيرادات خدمات - فرع فرعي | D31: إيرادات خدمات | F31: 50920
A32: 2026-02-10 | B32: 2 | C32: إيرادات أخرى - فرع رئيسي | D32: إيرادات أخرى | F32: 3348
A33: 2026-02-25 | B33: 2 | C33: إيرادات أخرى - فرع فرعي | D33: إيرادات أخرى | F33: 2052
A34: 2026-02-10 | B34: 2 | C34: مواد خام مباشرة - دفعة أولى | D34: مواد خام مباشرة | E34: 111972
A35: 2026-02-25 | B35: 2 | C35: مواد خام مباشرة - دفعة ثانية | D35: مواد خام مباشرة | E35: 68628
A36: 2026-02-10 | B36: 2 | C36: أجور مباشرة - دفعة أولى | D36: أجور مباشرة | E36: 47988
A37: 2026-02-25 | B37: 2 | C37: أجور مباشرة - دفعة ثانية | D37: أجور مباشرة | E37: 29412
A38: 2026-02-10 | B38: 2 | C38: تكاليف صناعية غير مباشرة - دفعة أولى | D38: تكاليف صناعية غير مباشرة | E38: 31992
A39: 2026-02-25 | B39: 2 | C39: تكاليف صناعية غير مباشرة - دفعة ثانية | D39: تكاليف صناعية غير مباشرة | E39: 19608
A40: 2026-02-10 | B40: 2 | C40: رواتب وأجور إدارية - دفعة أولى | D40: رواتب وأجور إدارية | E40: 57040
A41: 2026-02-25 | B41: 2 | C41: رواتب وأجور إدارية - دفعة ثانية | D41: رواتب وأجور إدارية | E41: 34960
A42: 2026-02-01 | B42: 2 | C42: قيد إيجار الشهري | D42: إيجار | E42: 30000
A43: 2026-02-10 | B43: 2 | C43: تسويق وإعلان - دفعة أولى | D43: تسويق وإعلان | E43: 9920
A44: 2026-02-25 | B44: 2 | C44: تسويق وإعلان - دفعة ثانية | D44: تسويق وإعلان | E44: 6080
A45: 2026-02-10 | B45: 2 | C45: مرافق (كهرباء/مياه) - دفعة أولى | D45: مرافق (كهرباء/مياه) | E45: 5084
... A53: 2026-02-25 | B53: 2 | C53: مصروفات متنوعة / غير مصنَّف - دفعة ثانية | D53: مصروفات متنوعة / غير مصنَّف | E53: 1178
A54: 2026-03-10 | B54: 3 | C54: مبيعات منتجات - فرع رئيسي | D54: مبيعات منتجات | F54: 324880
...

Sheet قائمة الدخل
B1: شركة النور للصناعات المتكاملة — قائمة الدخل (يناير–ديسمبر 2026) — ج.م
B3: بيانات مولَّدة بالكامل بالذكاء الاصطناعي (Claude) لأغراض اختبار برومبت تحليل مالي — ليست بيانات شركة حقيقية. | C3: يناير | D3: فبراير | E3: مارس | F3: أبريل | G3: مايو | H3: يونيو | I3: يوليو | J3: أغسطس | K3: سبتمبر | L3: أكتوبر | M3: نوفمبر | N3: ديسمبر | O3: الإجمالي السنوي
B6: الإيرادات
B7: مبيعات منتجات | C7: =SUMIFS('دفتر الأستاذ العام'!$F$2:$F$313,'دفتر الأستاذ العام'!$D$2:$D$313,"مبيعات منتجات",'دفتر الأستاذ العام'!$B$2:$B$313,1) | D7: =SUMIFS('دفتر الأستاذ العام'!$F$2:$F$313,'دفتر الأستاذ العام'!$D$2:$D$313,"مبيعات منتجات",'دفتر الأستاذ العام'!$B$2:$B$313,2) | E7: =SUMIFS('دفتر الأستاذ العام'!$F$2:$F$313,'دفتر الأستاذ العام'!$D$2:$D$313,"مبيعات منتجات",'دفتر الأستاذ العام'!$B$2:$B$313,3) | F7: =SUMIFS('دفتر الأستاذ العام'!$F$2:$F$313,'دفتر الأستاذ العام'!$D$2:$D$313,"مبيعات منتجات",'دفتر الأستاذ العام'!$B$2:$B$313,4) | G7: =SUMIFS('دفتر الأستاذ العام'!$F$2:$F$313,'دفتر الأستاذ العام'!$D$2:$D$313,"مبيعات منتجات",'دفتر الأستاذ العام'!$B$2:$B$313,5) | H7: =SUMIFS('دفتر الأستاذ العام'!$F$2:$F$313,'دفتر الأستاذ العام'!$D$2:$D$313,"مبيعات منتجات",'دفتر الأستاذ العام'!$B$2:$B$313,6) | I7: =SUMIFS('دفتر الأستاذ العام'!$F$2:$F$313,'دفتر الأستاذ العام'!$D$2:$D$313,"مبيعات منتجات",'دفتر الأستاذ العام'!$B$2:$B$313,7) | J7: =SUMIFS('دفتر الأستاذ العام'!$F$2:$F$313,'دفتر الأستاذ العام'!$D$2:$D$313,"مبيعات منتجات",'دفتر الأستاذ العام'!$B$2:$B$313,8) | K7: =SUMIFS('دفتر الأستاذ العام'!$F$2:$F$313,'دفتر الأستاذ العام'!$D$2:$D$313,"مبيعات منتجات",'دفتر الأستاذ العام'!$B$2:$B$313,9) | L7: =SUMIFS('دفتر الأستاذ العام'!$F$2:$F$313,'دفتر الأستاذ العام'!$D$2:$D$313,"مبيعات منتجات",'دفتر الأستاذ العام'!$B$2:$B$313,10) | M7: =SUMIFS('دفتر الأستاذ العام'!$F$2:$F$313,'دفتر الأستاذ العام'!$D$2:$D$313,"مبيعات منتجات",'دفتر الأستاذ العام'!$B$2:$B$313,11) | N7: =SUMIFS('دفتر الأستاذ العام'!$F$2:$F$313,'دفتر الأستاذ العام'!$D$2:$D$313,"مبيعات منتجات",'دفتر الأستاذ العام'!$B$2:$B$313,12) | O7: =SUM(C7:N7)
B8: إيرادات خدمات | C8: =SUMIFS('دفتر الأستاذ العام'!$F$2:$F$313,'دفتر الأستاذ العام'!$D$2:$D$313,"إيرادات خدمات",'دفتر الأستاذ العام'!$B$2:$B$313,1) | D8: =SUMIFS('دفتر الأستاذ العام'!$F$2:$F$313,'دفتر الأستاذ العام'!$D$2:$D$313,"إيرادات خدمات",'دفتر الأستاذ العام'!$B$2:$B$313,2) | E8: =SUMIFS('دفتر الأستاذ العام'!$F$2:$F$313,'دفتر الأستاذ العام'!$D$2:$D$313,"إيرادات خدمات",'دفتر الأستاذ العام'!$B$2:$B$313,3) | F8: =SUMIFS('دفتر الأستاذ العام'!$F$2:$F$313,'دفتر الأستاذ العام'!$D$2:$D$313,"إيرادات خدمات",'دفتر الأستاذ العام'!$B$2:$B$313,4) | G8: =SUMIFS('دفتر الأستاذ العام'!$F$2:$F$313,'دفتر الأستاذ العام'!$D$2:$D$313,"إيرادات خدمات",'دفتر الأستاذ العام'!$B$2:$B$313,5) | H8: =SUMIFS('دفتر الأستاذ العام'!$F$2:$F$313,'دفتر الأستاذ العام'!$D$2:$D$313,"إيرادات خدمات",'دفتر الأستاذ العام'!$B$2:$B$313,6) | I8: =SUMIFS('دفتر الأستاذ العام'!$F$2:$F$313,'دفتر الأستاذ العام'!$D$2:$D$313,"إيرادات خدمات",'دفتر الأستاذ العام'!$B$2:$B$313,7) | J8: =SUMIFS('دفتر الأستاذ العام'!$F$2:$F$313,'دفتر الأستاذ العام'!$D$2:$D$313,"إيرادات خدمات",'دفتر الأستاذ العام'!$B$2:$B$313,8) | K8: =SUMIFS('دفتر الأستاذ العام'!$F$2:$F$313,'دفتر الأستاذ العام'!$D$2:$D$313,"إيرادات خدمات",'دفتر الأستاذ العام'!$B$2:$B$313,9) | L8: =SUMIFS('دفتر الأستاذ العام'!$F$2:$F$313,'دفتر الأستاذ العام'!$D$2:$D$313,"إيرادات خدمات",'دفتر الأستاذ العام'!$B$2:$B$313,10) | M8: =SUMIFS('دفتر الأستاذ العام'!$F$2:$F$313,'دفتر الأستاذ العام'!$D$2:$D$313,"إيرادات خدمات",'دفتر الأستاذ العام'!$B$2:$B$313,11) | N8: =SUMIFS('دفتر الأستاذ العام'!$F$2:$F$313,'دفتر الأستاذ العام'!$D$2:$D$313,"إيرادات خدمات",'دفتر الأستاذ العام'!$B$2:$B$313,12) | O8: =SUM(C8:N8)
B9: إيرادات أخرى | C9: =SUMIFS('دفتر الأستاذ العام'!$F$2:$F$313,'دفتر الأستاذ العام'!$D$2:$D$313,"إيرادات أخرى",'دفتر الأستاذ العام'!$B$2:$B$313,1) | D9: =SUMIFS('دفتر الأستاذ العام'!$F$2:$F$313,'دفتر الأستاذ العام'!$D$2:$D$313,"إيرادات أخرى",'دفتر الأستاذ العام'!$B$2:$B$313,2) | E9: =SUMIFS('دفتر الأستاذ العام'!$F$2:$F$313,'دفتر الأستاذ العام'!$D$2:$D$313,"إيرادات أخرى",'دفتر الأستاذ العام'!$B$2:$B$313,3) | F9: =SUMIFS('دفتر الأستاذ العام'!$F$2:$F$313,'دفتر الأستاذ العام'!$D$2:$D$313,"إيرادات أخرى",'دفتر الأستاذ العام'!$B$2:$B$313,4) | G9: =SUMIFS('دفتر الأستاذ العام'!$F$2:$F$313,'دفتر الأستاذ العام'!$D$2:$D$313,"إيرادات أخرى",'دفتر الأستاذ العام'!$B$2:$B$313,5) | H9: =SUMIFS('دفتر الأستاذ العام'!$F$2:$F$313,'دفتر الأستاذ العام'!$D$2:$D$313,"إيرادات أخرى",'دفتر الأستاذ العام'!$B$2:$B$313,6) | I9: =SUMIFS('دفتر الأستاذ العام'!$F$2:$F$313,'دفتر الأستاذ العام'!$D$2:$D$313,"إيرادات أخرى",'دفتر الأستاذ العام'!$B$2:$B$313,7) | J9: =SUMIFS('دفتر الأستاذ العام'!$F$2:$F$313,'دفتر الأستاذ العام'!$D$2:$D$313,"إيرادات أخرى",'دفتر الأستاذ العام'!$B$2:$B$313,8) | K9: =SUMIFS('دفتر الأستاذ العام'!$F$2:$F$313,'دفتر الأستاذ العام'!$D$2:$D$313,"إيرادات أخرى",'دفتر الأستاذ العام'!$B$2:$B$313,9) | L9: =SUMIFS('دفتر الأستاذ العام'!$F$2:$F$313,'دفتر الأستاذ العام'!$D$2:$D$313,"إيرادات أخرى",'دفتر الأستاذ العام'!$B$2:$B$313,10) | M9: =SUMIFS('دفتر الأستاذ العام'!$F$2:$F$313,'دفتر الأستاذ العام'!$D$2:$D$313,"إيرادات أخرى",'دفتر الأستاذ العام'!$B$2:$B$313,11) | N9: =SUMIFS('دفتر الأستاذ العام'!$F$2:$F$313,'دفتر الأستاذ العام'!$D$2:$D$313,"إيرادات أخرى",'دفتر الأستاذ العام'!$B$2:$B$313,12) | O9: =SUM(C9:N9)
B10: إجمالي الإيرادات | C10: =C7+C8+C9 | D10: =D7+D8+D9 | E10: =E7+E8+E9 | F10: =F7+F8+F9 | G10: =G7+G8+G9 | H10: =H7+H8+H9 | I10: =I7+I8+I9 | J10: =J7+J8+J9 | ... N10: =N7+N8+N9 | O10: =SUM(C10:N10)
B12: تكلفة الإنتاج المباشرة (COGS)
B13: مواد خام مباشرة | C13: =SUMIFS('دفتر الأستاذ العام'!$E$2:$E$313,'دفتر الأستاذ العام'!$D$2:$D$313,"مواد خام مباشرة",'دفتر الأستاذ العام'!$B$2:$B$313,1) | D13: =SUMIFS('دفتر الأستاذ العام'!$E$2:$E$313,'دفتر الأستاذ العام'!$D$2:$D$313,"مواد خام مباشرة",'دفتر الأستاذ العام'!$B$2:$B$313,2) | E13: =SUMIFS('دفتر الأستاذ العام'!$E$2:$E$313,'دفتر الأستاذ العام'!$D$2:$D$313,"مواد خام مباشرة",'دفتر الأستاذ العام'!$B$2:$B$313,3) | F13: =SUMIFS('دفتر الأستاذ العام'!$E$2:$E$313,'دفتر الأستاذ العام'!$D$2:$D$313,"مواد خام مباشرة",'دفتر الأستاذ العام'!$B$2:$B$313,4) | G13: =SUMIFS('دفتر الأستاذ العام'!$E$2:$E$313,'دفتر الأستاذ العام'!$D$2:$D$313,"مواد خام مباشرة",'دفتر الأستاذ العام'!$B$2:$B$313,5) | H13: =SUMIFS('دفتر الأستاذ العام'!$E$2:$E$313,'دفتر الأستاذ العام'!$D$2:$D$313,"مواد خام مباشرة",'دفتر الأستاذ العام'!$B$2:$B$313,6) | I13: =SUMIFS('دفتر الأستاذ العام'!$E$2:$E$313,'دفتر الأستاذ العام'!$D$2:$D$313,"مواد خام مباشرة",'دفتر الأستاذ العام'!$B$2:$B$313,7) | J13: =SUMIFS('دفتر الأستاذ العام'!$E$2:$E$313,'دفتر الأستاذ العام'!$D$2:$D$313,"مواد خام مباشرة",'دفتر الأستاذ العام'!$B$2:$B$313,8) | K13: =SUMIFS('دفتر الأستاذ العام'!$E$2:$E$313,'دفتر الأستاذ العام'!$D$2:$D$313,"مواد خام مباشرة",'دفتر الأستاذ العام'!$B$2:$B$313,9) | L13: =SUMIFS('دفتر الأستاذ العام'!$E$2:$E$313,'دفتر الأستاذ العام'!$D$2:$D$313,"مواد خام مباشرة",'دفتر الأستاذ العام'!$B$2:$B$313,10) | M13: =SUMIFS('دفتر الأستاذ العام'!$E$2:$E$313,'دفتر الأستاذ العام'!$D$2:$D$313,"مواد خام مباشرة",'دفتر الأستاذ العام'!$B$2:$B$313,11) | N13: =SUMIFS('دفتر الأستاذ العام'!$E$2:$E$313,'دفتر الأستاذ العام'!$D$2:$D$313,"مواد خام مباشرة",'دفتر الأستاذ العام'!$B$2:$B$313,12) | O13: =SUM(C13:N13)
B14: أجور مباشرة | C14: =SUMIFS('دفتر الأستاذ العام'!$E$2:$E$313,'دفتر الأستاذ العام'!$D$2:$D$313,"أجور مباشرة",'دفتر الأستاذ العام'!$B$2:$B$313,1) | D14: =SUMIFS('دفتر الأستاذ العام'!$E$2:$E$313,'دفتر الأستاذ العام'!$D$2:$D$313,"أجور مباشرة",'دفتر الأستاذ العام'!$B$2:$B$313,2) | E14: =SUMIFS('دفتر الأستاذ العام'!$E$2:$E$313,'دفتر الأستاذ العام'!$D$2:$D$313,"أجور مباشرة",'دفتر الأستاذ العام'!$B$2:$B$313,3) | F14: =SUMIFS('دفتر الأستاذ العام'!$E$2:$E$313,'دفتر الأستاذ العام'!$D$2:$D$313,"أجور مباشرة",'دفتر الأستاذ العام'!$B$2:$B$313,4) | G14: =SUMIFS('دفتر الأستاذ العام'!$E$2:$E$313,'دفتر الأستاذ العام'!$D$2:$D$313,"أجور مباشرة",'دفتر الأستاذ العام'!$B$2:$B$313,5) | H14: =SUMIFS('دفتر الأستاذ العام'!$E$2:$E$313,'دفتر الأستاذ العام'!$D$2:$D$313,"أجور مباشرة",'دفتر الأستاذ العام'!$B$2:$B$313,6) | I14: =SUMIFS('دفتر الأستاذ العام'!$E$2:$E$313,'دفتر الأستاذ العام'!$D$2:$D$313,"أجور مباشرة",'دفتر الأستاذ العام'!$B$2:$B$313,7) | J14: =SUMIFS('دفتر الأستاذ العام'!$E$2:$E$313,'دفتر الأستاذ العام'!$D$2:$D$313,"أجور مباشرة",'دفتر الأستاذ العام'!$B$2:$B$313,8) | K14: =SUMIFS('دفتر الأستاذ العام'!$E$2:$E$313,'دفتر الأستاذ العام'!$D$2:$D$313,"أجور مباشرة",'دفتر الأستاذ العام'!$B$2:$B$313,9) | L14: =SUMIFS('دفتر الأستاذ العام'!$E$2:$E$313,'دفتر الأستاذ العام'!$D$2:$D$313,"أجور مباشرة",'دفتر الأستاذ العام'!$B$2:$B$313,10) | M14: =SUMIFS('دفتر الأستاذ العام'!$E$2:$E$313,'دفتر الأستاذ العام'!$D$2:$D$313,"أجور مباشرة",'دفتر الأستاذ العام'!$B$2:$B$313,11) | N14: =SUMIFS('دفتر الأستاذ العام'!$E$2:$E$313,'دفتر الأستاذ العام'!$D$2:$D$313,"أجور مباشرة",'دفتر الأستاذ العام'!$B$2:$B$313,12) | O14: =SUM(C14:N14)
B15: تكاليف صناعية غير مباشرة | C15: =SUMIFS('دفتر الأستاذ العام'!$E$2:$E$313,'دفتر الأستاذ العام'!$D$2:$D$313,"تكاليف صناعية غير مباشرة",'دفتر الأستاذ العام'!$B$2:$B$313,1) | D15: =SUMIFS('دفتر الأستاذ العام'!$E$2:$E$313,'دفتر الأستاذ العام'!$D$2:$D$313,"تكاليف صناعية غير مباشرة",'دفتر الأستاذ العام'!$B$2:$B$313,2) | E15: =SUMIFS('دفتر الأستاذ العام'!$E$2:$E$313,'دفتر الأستاذ العام'!$D$2:$D$313,"تكاليف صناعية غير مباشرة",'دفتر الأستاذ العام'!$B$2:$B$313,3) | F15: =SUMIFS('دفتر الأستاذ العام'!$E$2:$E$313,'دفتر الأستاذ العام'!$D$2:$D$313,"تكاليف صناعية غير مباشرة",'دفتر الأستاذ العام'!$B$2:$B$313,4) | G15: =SUMIFS('دفتر الأستاذ العام'!$E$2:$E$313,'دفتر الأستاذ العام'!$D$2:$D$313,"تكاليف صناعية غير مباشرة",'دفتر الأستاذ العام'!$B$2:$B$313,5) | H15: =SUMIFS('دفتر الأستاذ العام'!$E$2:$E$313,'دفتر الأستاذ العام'!$D$2:$D$313,"تكاليف صناعية غير مباشرة",'دفتر الأستاذ العام'!$B$2:$B$313,6) | I15: =SUMIFS('دفتر الأستاذ العام'!$E$2:$E$313,'دفتر الأستاذ العام'!$D$2:$D$313,"تكاليف صناعية غير مباشرة",'دفتر الأستاذ العام'!$B$2:$B$313,7) | J15: =SUMIFS('دفتر الأستاذ العام'!$E$2:$E$313,'دفتر الأستاذ العام'!$D$2:$D$313,"تكاليف صناعية غير مباشرة",'دفتر الأستاذ العام'!$B$2:$B$313,8) | K15: =SUMIFS('دفتر الأستاذ العام'!$E$2:$E$313,'دفتر الأستاذ العام'!$D$2:$D$313,"تكاليف صناعية غير مباشرة",'دفتر الأستاذ العام'!$B$2:$B$313,9) | L15: =SUMIFS('دفتر الأستاذ العام'!$E$2:$E$313,'دفتر الأستاذ العام'!$D$2:$D$313,"تكاليف صناعية غير مباشرة",'دفتر الأستاذ العام'!$B$2:$B$313,10) | M15: =SUMIFS('دفتر الأستاذ العام'!$E$2:$E$313,'دفتر الأستاذ العام'!$D$2:$D$313,"تكاليف صناعية غير مباشرة",'دفتر الأستاذ العام'!$B$2:$B$313,11) | N15: =SUMIFS('دفتر الأستاذ العام'!$E$2:$E$313,'دفتر الأستاذ العام'!$D$2:$D$313,"تكاليف صناعية غير مباشرة",'دفتر الأستاذ العام'!$B$2:$B$313,12) | O15: =SUM(C15:N15)
B16: إجمالي تكلفة الإنتاج المباشرة | C16: =C13+C14+C15 | D16: =D13+D14+D15 | E16: =E13+E14+E15 | F16: =F13+F14+F15 | G16: =G13+G14+G15 | H16: =H13+H14+H15 | I16: =I13+I14+I15 | J16: =J13+J14+J15 | ... N16: =N13+N14+N15 | O16: =SUM(C16:N16)
B17: مجمل الربح | C17: =C10-C16 | D17: =D10-D16 | E17: =E10-E16 | F17: =F10-F16 | G17: =G10-G16 | H17: =H10-H16 | I17: =I10-I16 | J17: =J10-J16 | ... N17: =N10-N16 | O17: =SUM(C17:N17)
B19: المصروفات التشغيلية
B20: رواتب وأجور إدارية | C20: =SUMIFS('دفتر الأستاذ العام'!$E$2:$E$313,'دفتر الأستاذ العام'!$D$2:$D$313,"رواتب وأجور إدارية",'دفتر الأستاذ العام'!$B$2:$B$313,1) | D20: =SUMIFS('دفتر الأستاذ العام'!$E$2:$E$313,'دفتر الأستاذ العام'!$D$2:$D$313,"رواتب وأجور إدارية",'دفتر الأستاذ العام'!$B$2:$B$313,2) | E20: =SUMIFS('دفتر الأستاذ العام'!$E$2:$E$313,'دفتر الأستاذ العام'!$D$2:$D$313,"رواتب وأجور إدارية",'دفتر الأستاذ العام'!$B$2:$B$313,3) | F20: =SUMIFS('دفتر الأستاذ العام'!$E$2:$E$313,'دفتر الأستاذ العام'!$D$2:$D$313,"رواتب وأجور إدارية",'دفتر الأستاذ العام'!$B$2:$B$313,4) | G20: =SUMIFS('دفتر الأستاذ العام'!$E$2:$E$313,'دفتر الأستاذ العام'!$D$2:$D$313,"رواتب وأجور إدارية",'دفتر الأستاذ العام'!$B$2:$B$313,5) | H20: =SUMIFS('دفتر الأستاذ العام'!$E$2:$E$313,'دفتر الأستاذ العام'!$D$2:$D$313,"رواتب وأجور إدارية",'دفتر الأستاذ العام'!$B$2:$B$313,6) | I20: =SUMIFS('دفتر الأستاذ العام'!$E$2:$E$313,'دفتر الأستاذ العام'!$D$2:$D$313,"رواتب وأجور إدارية",'دفتر الأستاذ العام'!$B$2:$B$313,7) | J20: =SUMIFS('دفتر الأستاذ العام'!$E$2:$E$313,'دفتر الأستاذ العام'!$D$2:$D$313,"رواتب وأجور إدارية",'دفتر الأستاذ العام'!$B$2:$B$313,8) | K20: =SUMIFS('دفتر الأستاذ العام'!$E$2:$E$313,'دفتر الأستاذ العام'!$D$2:$D$313,"رواتب وأجور إدارية",'دفتر الأستاذ العام'!$B$2:$B$313,9) | L20: =SUMIFS('دفتر الأستاذ العام'!$E$2:$E$313,'دفتر الأستاذ العام'!$D$2:$D$313,"رواتب وأجور إدارية",'دفتر الأستاذ العام'!$B$2:$B$313,10) | M20: =SUMIFS('دفتر الأستاذ العام'!$E$2:$E$313,'دفتر الأستاذ العام'!$D$2:$D$313,"رواتب وأجور إدارية",'دفتر الأستاذ العام'!$B$2:$B$313,11) | N20: =SUMIFS('دفتر الأستاذ العام'!$E$2:$E$313,'دفتر الأستاذ العام'!$D$2:$D$313,"رواتب وأجور إدارية",'دفتر الأستاذ العام'!$B$2:$B$313,12) | O20: =SUM(C20:N20)
B21: إيجار | C21: =SUMIFS('دفتر الأستاذ العام'!$E$2:$E$313,'دفتر الأستاذ العام'!$D$2:$D$313,"إيجار",'دفتر الأستاذ العام'!$B$2:$B$313,1) | D21: =SUMIFS('دفتر الأستاذ العام'!$E$2:$E$313,'دفتر الأستاذ العام'!$D$2:$D$313,"إيجار",'دفتر الأستاذ العام'!$B$2:$B$313,2) | E21: =SUMIFS('دفتر الأستاذ العام'!$E$2:$E$313,'دفتر الأستاذ العام'!$D$2:$D$313,"إيجار",'دفتر الأستاذ العام'!$B$2:$B$313,3) | F21: =SUMIFS('دفتر الأستاذ العام'!$E$2:$E$313,'دفتر الأستاذ العام'!$D$2:$D$313,"إيجار",'دفتر الأستاذ العام'!$B$2:$B$313,4) | G21: =SUMIFS('دفتر الأستاذ العام'!$E$2:$E$313,'دفتر الأستاذ العام'!$D$2:$D$313,"إيجار",'دفتر الأستاذ العام'!$B$2:$B$313,5) | H21: =SUMIFS('دفتر الأستاذ العام'!$E$2:$E$313,'دفتر الأستاذ العام'!$D$2:$D$313,"إيجار",'دفتر الأستاذ العام'!$B$2:$B$313,6) | I21: =SUMIFS('دفتر الأستاذ العام'!$E$2:$E$313,'دفتر الأستاذ العام'!$D$2:$D$313,"إيجار",'دفتر الأستاذ العام'!$B$2:$B$313,7) | J21: =SUMIFS('دفتر الأستاذ العام'!$E$2:$E$313,'دفتر الأستاذ العام'!$D$2:$D$313,"إيجار",'دفتر الأستاذ العام'!$B$2:$B$313,8) | K21: =SUMIFS('دفتر الأستاذ العام'!$E$2:$E$313,'دفتر الأستاذ العام'!$D$2:$D$313,"إيجار",'دفتر الأستاذ العام'!$B$2:$B$313,9) | L21: =SUMIFS('دفتر الأستاذ العام'!$E$2:$E$313,'دفتر الأستاذ العام'!$D$2:$D$313,"إيجار",'دفتر الأستاذ العام'!$B$2:$B$313,10) | M21: =SUMIFS('دفتر الأستاذ العام'!$E$2:$E$313,'دفتر الأستاذ العام'!$D$2:$D$313,"إيجار",'دفتر الأستاذ العام'!$B$2:$B$313,11) | N21: =SUMIFS('دفتر الأستاذ العام'!$E$2:$E$313,'دفتر الأستاذ العام'!$D$2:$D$313,"إيجار",'دفتر الأستاذ العام'!$B$2:$B$313,12) | O21: =SUM(C21:N21)
B22: تسويق وإعلان | C22: =SUMIFS('دفتر الأستاذ العام'!$E$2:$E$313,'دفتر الأستاذ العام'!$D$2:$D$313,"تسويق وإعلان",'دفتر الأستاذ العام'!$B$2:$B$313,1) | D22: =SUMIFS('دفتر الأستاذ العام'!$E$2:$E$313,'دفتر الأستاذ العام'!$D$2:$D$313,"تسويق وإعلان",'دفتر الأستاذ العام'!$B$2:$B$313,2) | E22: =SUMIFS('دفتر الأستاذ العام'!$E$2:$E$313,'دفتر الأستاذ العام'!$D$2:$D$313,"تسويق وإعلان",'دفتر الأستاذ العام'!$B$2:$B$313,3) | F22: =SUMIFS('دفتر الأستاذ العام'!$E$2:$E$313,'دفتر الأستاذ العام'!$D$2:$D$313,"تسويق وإعلان",'دفتر الأستاذ العام'!$B$2:$B$313,4) | G22: =SUMIFS('دفتر الأستاذ العام'!$E$2:$E$313,'دفتر الأستاذ العام'!$D$2:$D$313,"تسويق وإعلان",'دفتر الأستاذ العام'!$B$2:$B$313,5) | H22: =SUMIFS('دفتر الأستاذ العام'!$E$2:$E$313,'دفتر الأستاذ العام'!$D$2:$D$313,"تسويق وإعلان",'دفتر الأستاذ العام'!$B$2:$B$313,6) | I22: =SUMIFS('دفتر الأستاذ العام'!$E$2:$E$313,'دفتر الأستاذ العام'!$D$2:$D$313,"تسويق وإعلان",'دفتر الأستاذ العام'!$B$2:$B$313,7) | J22: =SUMIFS('دفتر الأستاذ العام'!$E$2:$E$313,'دفتر الأستاذ العام'!$D$2:$D$313,"تسويق وإعلان",'دفتر الأستاذ العام'!$B$2:$B$313,8) | K22: =SUMIFS('دفتر الأستاذ العام'!$E$2:$E$313,'دفتر الأستاذ العام'!$D$2:$D$313,"تسويق وإعلان",'دفتر الأستاذ العام'!$B$2:$B$313,9) | L22: =SUMIFS('دفتر الأستاذ العام'!$E$2:$E$313,'دفتر الأستاذ العام'!$D$2:$D$313,"تسويق وإعلان",'دفتر الأستاذ العام'!$B$2:$B$313,10) | M22: =SUMIFS('دفتر الأستاذ العام'!$E$2:$E$313,'دفتر الأستاذ العام'!$D$2:$D$313,"تسويق وإعلان",'دفتر الأستاذ العام'!$B$2:$B$313,11) | N22: =SUMIFS('دفتر الأستاذ العام'!$E$2:$E$313,'دفتر الأستاذ العام'!$D$2:$D$313,"تسويق وإعلان",'دفتر الأستاذ العام'!$B$2:$B$313,12) | O22: =SUM(C22:N22)
B23: مرافق (كهرباء/مياه) | C23: =SUMIFS('دفتر الأستاذ العام'!$E$2:$E$313,'دفتر الأستاذ العام'!$D$2:$D$313,"مرافق (كهرباء/مياه)",'دفتر الأستاذ العام'!$B$2:$B$313,1) | D23: =SUMIFS('دفتر الأستاذ العام'!$E$2:$E$313,'دفتر الأستاذ العام'!$D$2:$D$313,"مرافق (كهرباء/مياه)",'دفتر الأستاذ العام'!$B$2:$B$313,2) | E23: =SUMIFS('دفتر الأستاذ العام'!$E$2:$E$313,'دفتر الأستاذ العام'!$D$2:$D$313,"مرافق (كهرباء/مياه)",'دفتر الأستاذ العام'!$B$2:$B$313,3) | F23: =SUMIFS('دفتر الأستاذ العام'!$E$2:$E$313,'دفتر الأستاذ العام'!$D$2:$D$313,"مرافق (كهرباء/مياه)",'دفتر الأستاذ العام'!$B$2:$B$313,4) | G23: =SUMIFS('دفتر الأستاذ العام'!$E$2:$E$313,'دفتر الأستاذ العام'!$D$2:$D$313,"مرافق (كهرباء/مياه)",'دفتر الأستاذ العام'!$B$2:$B$313,5) | H23: =SUMIFS('دفتر الأستاذ العام'!$E$2:$E$313,'دفتر الأستاذ العام'!$D$2:$D$313,"مرافق (كهرباء/مياه)",'دفتر الأستاذ العام'!$B$2:$B$313,6) | I23: =SUMIFS('دفتر الأستاذ العام'!$E$2:$E$313,'دفتر الأستاذ العام'!$D$2:$D$313,"مرافق (كهرباء/مياه)",'دفتر الأستاذ العام'!$B$2:$B$313,7) | J23: =SUMIFS('دفتر الأستاذ العام'!$E$2:$E$313,'دفتر الأستاذ العام'!$D$2:$D$313,"مرافق (كهرباء/مياه)",'دفتر الأستاذ العام'!$B$2:$B$313,8) | K23: =SUMIFS('دفتر الأستاذ العام'!$E$2:$E$313,'دفتر الأستاذ العام'!$D$2:$D$313,"مرافق (كهرباء/مياه)",'دفتر الأستاذ العام'!$B$2:$B$313,9) | L23: =SUMIFS('دفتر الأستاذ العام'!$E$2:$E$313,'دفتر الأستاذ العام'!$D$2:$D$313,"مرافق (كهرباء/مياه)",'دفتر الأستاذ العام'!$B$2:$B$313,10) | M23: =SUMIFS('دفتر الأستاذ العام'!$E$2:$E$313,'دفتر الأستاذ العام'!$D$2:$D$313,"مرافق (كهرباء/مياه)",'دفتر الأستاذ العام'!$B$2:$B$313,11) | N23: =SUMIFS('دفتر الأستاذ العام'!$E$2:$E$313,'دفتر الأستاذ العام'!$D$2:$D$313,"مرافق (كهرباء/مياه)",'دفتر الأستاذ العام'!$B$2:$B$313,12) | O23: =SUM(C23:N23)
B24: صيانة | C24: =SUMIFS('دفتر الأستاذ العام'!$E$2:$E$313,'دفتر الأستاذ العام'!$D$2:$D$313,"صيانة",'دفتر الأستاذ العام'!$B$2:$B$313,1) | D24: =SUMIFS('دفتر الأستاذ العام'!$E$2:$E$313,'دفتر الأستاذ العام'!$D$2:$D$313,"صيانة",'دفتر الأستاذ العام'!$B$2:$B$313,2) | E24: =SUMIFS('دفتر الأستاذ العام'!$E$2:$E$313,'دفتر الأستاذ العام'!$D$2:$D$313,"صيانة",'دفتر الأستاذ العام'!$B$2:$B$313,3) | F24: =SUMIFS('دفتر الأستاذ العام'!$E$2:$E$313,'دفتر الأستاذ العام'!$D$2:$D$313,"صيانة",'دفتر الأستاذ العام'!$B$2:$B$313,4) | G24: =SUMIFS('دفتر الأستاذ العام'!$E$2:$E$313,'دفتر الأستاذ العام'!$D$2:$D$313,"صيانة",'دفتر الأستاذ العام'!$B$2:$B$313,5) | H24: =SUMIFS('دفتر الأستاذ العام'!$E$2:$E$313,'دفتر الأستاذ العام'!$D$2:$D$313,"صيانة",'دفتر الأستاذ العام'!$B$2:$B$313,6) | I24: =SUMIFS('دفتر الأستاذ العام'!$E$2:$E$313,'دفتر الأستاذ العام'!$D$2:$D$313,"صيانة",'دفتر الأستاذ العام'!$B$2:$B$313,7) | J24: =SUMIFS('دفتر الأستاذ العام'!$E$2:$E$313,'دفتر الأستاذ العام'!$D$2:$D$313,"صيانة",'دفتر الأستاذ العام'!$B$2:$B$313,8) | K24: =SUMIFS('دفتر الأستاذ العام'!$E$2:$E$313,'دفتر الأستاذ العام'!$D$2:$D$313,"صيانة",'دفتر الأستاذ العام'!$B$2:$B$313,9) | L24: =SUMIFS('دفتر الأستاذ العام'!$E$2:$E$313,'دفتر الأستاذ العام'!$D$2:$D$313,"صيانة",'دفتر الأستاذ العام'!$B$2:$B$313,10) | M24: =SUMIFS('دفتر الأستاذ العام'!$E$2:$E$313,'دفتر الأستاذ العام'!$D$2:$D$313,"صيانة",'دفتر الأستاذ العام'!$B$2:$B$313,11) | N24: =SUMIFS('دفتر الأستاذ العام'!$E$2:$E$313,'دفتر الأستاذ العام'!$D$2:$D$313,"صيانة",'دفتر الأستاذ العام'!$B$2:$B$313,12) | O24: =SUM(C24:N24)
B25: تأمين | C25: =SUMIFS('دفتر الأستاذ العام'!$E$2:$E$313,'دفتر الأستاذ العام'!$D$2:$D$313,"تأمين",'دفتر الأستاذ العام'!$B$2:$B$313,1) | D25: =SUMIFS('دفتر الأستاذ العام'!$E$2:$E$313,'دفتر الأستاذ العام'!$D$2:$D$313,"تأمين",'دفتر الأستاذ العام'!$B$2:$B$313,2) | E25: =SUMIFS('دفتر الأستاذ العام'!$E$2:$E$313,'دفتر الأستاذ العام'!$D$2:$D$313,"تأمين",'دفتر الأستاذ العام'!$B$2:$B$313,3) | F25: =SUMIFS('دفتر الأستاذ العام'!$E$2:$E$313,'دفتر الأستاذ العام'!$D$2:$D$313,"تأمين",'دفتر الأستاذ العام'!$B$2:$B$313,4) | G25: =SUMIFS('دفتر الأستاذ العام'!$E$2:$E$313,'دفتر الأستاذ العام'!$D$2:$D$313,"تأمين",'دفتر الأستاذ العام'!$B$2:$B$313,5) | H25: =SUMIFS('دفتر الأستاذ العام'!$E$2:$E$313,'دفتر الأستاذ العام'!$D$2:$D$313,"تأمين",'دفتر الأستاذ العام'!$B$2:$B$313,6) | I25: =SUMIFS('دفتر الأستاذ العام'!$E$2:$E$313,'دفتر الأستاذ العام'!$D$2:$D$313,"تأمين",'دفتر الأستاذ العام'!$B$2:$B$313,7) | J25: =SUMIFS('دفتر الأستاذ العام'!$E$2:$E$313,'دفتر الأستاذ العام'!$D$2:$D$313,"تأمين",'دفتر الأستاذ العام'!$B$2:$B$313,8) | K25: =SUMIFS('دفتر الأستاذ العام'!$E$2:$E$313,'دفتر الأستاذ العام'!$D$2:$D$313,"تأمين",'دفتر الأستاذ العام'!$B$2:$B$313,9) | L25: =SUMIFS('دفتر الأستاذ العام'!$E$2:$E$313,'دفتر الأستاذ العام'!$D$2:$D$313,"تأمين",'دفتر الأستاذ العام'!$B$2:$B$313,10) | M25: =SUMIFS('دفتر الأستاذ العام'!$E$2:$E$313,'دفتر الأستاذ العام'!$D$2:$D$313,"تأمين",'دفتر الأستاذ العام'!$B$2:$B$313,11) | N25: =SUMIFS('دفتر الأستاذ العام'!$E$2:$E$313,'دفتر الأستاذ العام'!$D$2:$D$313,"تأمين",'دفتر الأستاذ العام'!$B$2:$B$313,12) | O25: =SUM(C25:N25)
B26: أتعاب مهنية | C26: =SUMIFS('دفتر الأستاذ العام'!$E$2:$E$313,'دفتر الأستاذ العام'!$D$2:$D$313,"أتعاب مهنية",'دفتر الأستاذ العام'!$B$2:$B$313,1) | D26: =SUMIFS('دفتر الأستاذ العام'!$E$2:$E$313,'دفتر الأستاذ العام'!$D$2:$D$313,"أتعاب مهنية",'دفتر الأستاذ العام'!$B$2:$B$313,2) | E26: =SUMIFS('دفتر الأستاذ العام'!$E$2:$E$313,'دفتر الأستاذ العام'!$D$2:$D$313,"أتعاب مهنية",'دفتر الأستاذ العام'!$B$2:$B$313,3) | F26: =SUMIFS('دفتر الأستاذ العام'!$E$2:$E$313,'دفتر الأستاذ العام'!$D$2:$D$313,"أتعاب مهنية",'دفتر الأستاذ العام'!$B$2:$B$313,4) | G26: =SUMIFS('دفتر الأستاذ العام'!$E$2:$E$313,'دفتر الأستاذ العام'!$D$2:$D$313,"أتعاب مهنية",'دفتر الأستاذ العام'!$B$2:$B$313,5) | H26: =SUMIFS('دفتر الأستاذ العام'!$E$2:$E$313,'دفتر الأستاذ العام'!$D$2:$D$313,"أتعاب مهنية",'دفتر الأستاذ العام'!$B$2:$B$313,6) | I26: =SUMIFS('دفتر الأستاذ العام'!$E$2:$E$313,'دفتر الأستاذ العام'!$D$2:$D$313,"أتعاب مهنية",'دفتر الأستاذ العام'!$B$2:$B$313,7) | J26: =SUMIFS('دفتر الأستاذ العام'!$E$2:$E$313,'دفتر الأستاذ العام'!$D$2:$D$313,"أتعاب مهنية",'دفتر الأستاذ العام'!$B$2:$B$313,8) | K26: =SUMIFS('دفتر الأستاذ العام'!$E$2:$E$313,'دفتر الأستاذ العام'!$D$2:$D$313,"أتعاب مهنية",'دفتر الأستاذ العام'!$B$2:$B$313,9) | L26: =SUMIFS('دفتر الأستاذ العام'!$E$2:$E$313,'دفتر الأستاذ العام'!$D$2:$D$313,"أتعاب مهنية",'دفتر الأستاذ العام'!$B$2:$B$313,10) | M26: =SUMIFS('دفتر الأستاذ العام'!$E$2:$E$313,'دفتر الأستاذ العام'!$D$2:$D$313,"أتعاب مهنية",'دفتر الأستاذ العام'!$B$2:$B$313,11) | N26: =SUMIFS('دفتر الأستاذ العام'!$E$2:$E$313,'دفتر الأستاذ العام'!$D$2:$D$313,"أتعاب مهنية",'دفتر الأستاذ العام'!$B$2:$B$313,12) | O26: =SUM(C26:N26)
B27: إهلاك | C27: =SUMIFS('دفتر الأستاذ العام'!$E$2:$E$313,'دفتر الأستاذ العام'!$D$2:$D$313,"إهلاك",'دفتر الأستاذ العام'!$B$2:$B$313,1) | D27: =SUMIFS('دفتر الأستاذ العام'!$E$2:$E$313,'دفتر الأستاذ العام'!$D$2:$D$313,"إهلاك",'دفتر الأستاذ العام'!$B$2:$B$313,2) | E27: =SUMIFS('دفتر الأستاذ العام'!$E$2:$E$313,'دفتر الأستاذ العام'!$D$2:$D$313,"إهلاك",'دفتر الأستاذ العام'!$B$2:$B$313,3) | F27: =SUMIFS('دفتر الأستاذ العام'!$E$2:$E$313,'دفتر الأستاذ العام'!$D$2:$D$313,"إهلاك",'دفتر الأستاذ العام'!$B$2:$B$313,4) | G27: =SUMIFS('دفتر الأستاذ العام'!$E$2:$E$313,'دفتر الأستاذ العام'!$D$2:$D$313,"إهلاك",'دفتر الأستاذ العام'!$B$2:$B$313,5) | H27: =SUMIFS('دفتر الأستاذ العام'!$E$2:$E$313,'دفتر الأستاذ العام'!$D$2:$D$313,"إهلاك",'دفتر الأستاذ العام'!$B$2:$B$313,6) | I27: =SUMIFS('دفتر الأستاذ العام'!$E$2:$E$313,'دفتر الأستاذ العام'!$D$2:$D$313,"إهلاك",'دفتر الأستاذ العام'!$B$2:$B$313,7) | J27: =SUMIFS('دفتر الأستاذ العام'!$E$2:$E$313,'دفتر الأستاذ العام'!$D$2:$D$313,"إهلاك",'دفتر الأستاذ العام'!$B$2:$B$313,8) | K27: =SUMIFS('دفتر الأستاذ العام'!$E$2:$E$313,'دفتر الأستاذ العام'!$D$2:$D$313,"إهلاك",'دفتر الأستاذ العام'!$B$2:$B$313,9) | L27: =SUMIFS('دفتر الأستاذ العام'!$E$2:$E$313,'دفتر الأستاذ العام'!$D$2:$D$313,"إهلاك",'دفتر الأستاذ العام'!$B$2:$B$313,10) | M27: =SUMIFS('دفتر الأستاذ العام'!$E$2:$E$313,'دفتر الأستاذ العام'!$D$2:$D$313,"إهلاك",'دفتر الأستاذ العام'!$B$2:$B$313,11) | N27: =SUMIFS('دفتر الأستاذ العام'!$E$2:$E$313,'دفتر الأستاذ العام'!$D$2:$D$313,"إهلاك",'دفتر الأستاذ العام'!$B$2:$B$313,12) | O27: =SUM(C27:N27)
B28: مصروفات متنوعة / غير مصنَّف | C28: =SUMIFS('دفتر الأستاذ العام'!$E$2:$E$313,'دفتر الأستاذ العام'!$D$2:$D$313,"مصروفات متنوعة / غير مصنَّف",'دفتر الأستاذ العام'!$B$2:$B$313,1) | D28: =SUMIFS('دفتر الأستاذ العام'!$E$2:$E$313,'دفتر الأستاذ العام'!$D$2:$D$313,"مصروفات متنوعة / غير مصنَّف",'دفتر الأستاذ العام'!$B$2:$B$313,2) | E28: =SUMIFS('دفتر الأستاذ العام'!$E$2:$E$313,'دفتر الأستاذ العام'!$D$2:$D$313,"مصروفات متنوعة / غير مصنَّف",'دفتر الأستاذ العام'!$B$2:$B$313,3) | F28: =SUMIFS('دفتر الأستاذ العام'!$E$2:$E$313,'دفتر الأستاذ العام'!$D$2:$D$313,"مصروفات متنوعة / غير مصنَّف",'دفتر الأستاذ العام'!$B$2:$B$313,4) | G28: =SUMIFS('دفتر الأستاذ العام'!$E$2:$E$313,'دفتر الأستاذ العام'!$D$2:$D$313,"مصروفات متنوعة / غير مصنَّف",'دفتر الأستاذ العام'!$B$2:$B$313,5) | H28: =SUMIFS('دفتر الأستاذ العام'!$E$2:$E$313,'دفتر الأستاذ العام'!$D$2:$D$313,"مصروفات متنوعة / غير مصنَّف",'دفتر الأستاذ العام'!$B$2:$B$313,6) | I28: =SUMIFS('دفتر الأستاذ العام'!$E$2:$E$313,'دفتر الأستاذ العام'!$D$2:$D$313,"مصروفات متنوعة / غير مصنَّف",'دفتر الأستاذ العام'!$B$2:$B$313,7) | J28: =SUMIFS('دفتر الأستاذ العام'!$E$2:$E$313,'دفتر الأستاذ العام'!$D$2:$D$313,"مصروفات متنوعة / غير مصنَّف",'دفتر الأستاذ العام'!$B$2:$B$313,8) | K28: =SUMIFS('دفتر الأستاذ العام'!$E$2:$E$313,'دفتر الأستاذ العام'!$D$2:$D$313,"مصروفات متنوعة / غير مصنَّف",'دفتر الأستاذ العام'!$B$2:$B$313,9) | L28: =SUMIFS('دفتر الأستاذ العام'!$E$2:$E$313,'دفتر الأستاذ العام'!$D$2:$D$313,"مصروفات متنوعة / غير مصنَّف",'دفتر الأستاذ العام'!$B$2:$B$313,10) | M28: =SUMIFS('دفتر الأستاذ العام'!$E$2:$E$313,'دفتر الأستاذ العام'!$D$2:$D$313,"مصروفات متنوعة / غير مصنَّف",'دفتر الأستاذ العام'!$B$2:$B$313,11) | N28: =SUMIFS('دفتر الأستاذ العام'!$E$2:$E$313,'دفتر الأستاذ العام'!$D$2:$D$313,"مصروفات متنوعة / غير مصنَّف",'دفتر الأستاذ العام'!$B$2:$B$313,12) | O28: =SUM(C28:N28)
B29: إجمالي المصروفات التشغيلية (محسوب) | C29: =C20+C21+C22+C23+C24+C25+C26+C27+C28 | D29: =D20+D21+D22+D23+D24+D25+D26+D27+D28 | E29: =E20+E21+E22+E23+E24+E25+E26+E27+E28 | F29: =F20+F21+F22+F23+F24+F25+F26+F27+F28 | G29: =G20+G21+G22+G23+G24+G25+G26+G27+G28 | H29: =H20+H21+H22+H23+H24+H25+H26+H27+H28 | I29: =I20+I21+I22+I23+I24+I25+I26+I27+I28 | J29: =J20+J21+J22+J23+J24+J25+J26+J27+J28 | ... N29: =N20+N21+N22+N23+N24+N25+N26+N27+N28 | O29: =SUM(C29:N29)
B30: إجمالي المصروفات التشغيلية (مُصرَّح به) | C30: 174750 | D30: 176500 | E30: 178250 | F30: 191000 | G30: 181750 | H30: 183500 | I30: 416750 | J30: 187000 | K30: 190250 | L30: 190500 | M30: 192250 | N30: 194000 | O30: =SUM(C30:N30)
B32: الربح التشغيلي | C32: =C17-C29 | D32: =D17-D29 | E32: =E17-E29 | F32: =F17-F29 | G32: =G17-G29 | H32: =H17-H29 | I32: =I17-I29 | J32: =J17-J29 | ... N32: =N17-N29 | O32: =SUM(C32:N32)
B33: صافي الربح / الخسارة | C33: =C17-C29 | D33: =D17-D29 | E33: =E17-E29 | F33: =F17-F29 | G33: =G17-G29 | H33: =H17-H29 | I33: =I17-I29 | J33: =J17-J29 | ... N33: =N17-N29 | O33: =SUM(C33:N33)

Sheet الميزانية العمومية
B1: شركة النور للصناعات المتكاملة — الميزانية العمومية (كما في 31 ديسمبر 2026) — ج.م
B3: بيانات مولَّدة بالكامل بالذكاء الاصطناعي (Claude) لأغراض اختبار برومبت تحليل مالي — ليست بيانات شركة حقيقية.
B4: النقدية وما في حكمها | C4: 500000
B5: ذمم مدينة (عملاء) | C5: 1000200
B6: المخزون (بضاعة تامة + تحت التشغيل) | C6: 1600000
B7: إجمالي الأصول المتداولة | C7: =C4+C5+C6
B9: الآلات والمعدات (بالتكلفة) | C9: 2600000
B10: يُخصم: مجمع الإهلاك | C10: =-'قائمة الدخل'!$O$27
B11: صافي الأصول الثابتة | C11: =C9+C10
B13: إجمالي الأصول (محسوب) | C13: =C7+C11
B14: إجمالي الأصول (كما ورد في ميزان المراجعة) | C14: 5558500
B16: الخصوم وحقوق الملكية (Liabilities & Equity)
B17: ذمم دائنة (موردون) | C17: 600000
B18: قرض طويل الأجل | C18: 1200000
B19: إجمالي الخصوم | C19: =C17+C18
B21: رأس المال | C21: 1500000
B22: الأرباح المحتجزة أول المدة (1 يناير 2026) | C22: 270000
B23: صافي ربح العام (من قائمة الدخل) | C23: ='قائمة الدخل'!$O$33
B24: الأرباح المحتجزة آخر المدة (محسوبة) | C24: =C22+C23
B25: الأرباح المحتجزة آخر المدة (كما في ميزان المراجعة) | C25: 2251700
B27: إجمالي حقوق الملكية (محسوب) | C27: =C21+C24
B28: إجمالي الخصوم وحقوق الملكية | C28: =C19+C27
